<?xml version="1.0" ?>
<!-- =================================================================================== -->
<!-- |    This document was autogenerated by xacro from ros\src\description\urdf\robot.urdf.xacro | -->
<!-- |    EDITING THIS FILE BY HAND IS NOT RECOMMENDED                                 | -->
<!-- =================================================================================== -->
<!--
  Rudy humanoid — kinematic skeleton for Phase 1.
  Joint limits mirror mr_robot config/robot.yaml (RS03 caps: 60 Nm, 50 rad/s).
  Frame convention: x forward, y left, z up. Left arm attaches on +y side of torso.
-->
<robot name="robot">
  <link name="base_link">
    <visual>
      <origin rpy="0 0 0" xyz="0 0 0"/>
      <geometry>
        <box size="0.35 0.35 0.04"/>
      </geometry>
      <material name="base_link_mat">
        <color rgba="0.2 0.2 0.25 1"/>
      </material>
    </visual>
    <collision>
      <origin rpy="0 0 0" xyz="0 0 0"/>
      <geometry>
        <box size="0.35 0.35 0.04"/>
      </geometry>
    </collision>
    <inertial>
      <origin rpy="0 0 0" xyz="0 0 0"/>
      <mass value="2.0"/>
      <inertia ixx="0.02068333333333333" ixy="0.0" ixz="0.0" iyy="0.02068333333333333" iyz="0.0" izz="0.040833333333333326"/>
    </inertial>
  </link>
  <link name="torso_lower_link">
    <visual>
      <origin rpy="0 0 0" xyz="0 0 0"/>
      <geometry>
        <box size="0.2 0.16 0.23"/>
      </geometry>
      <material name="torso_lower_link_mat">
        <color rgba="0.35 0.35 0.4 1"/>
      </material>
    </visual>
    <collision>
      <origin rpy="0 0 0" xyz="0 0 0"/>
      <geometry>
        <box size="0.2 0.16 0.23"/>
      </geometry>
    </collision>
    <inertial>
      <origin rpy="0 0 0" xyz="0 0 0"/>
      <mass value="8.0"/>
      <inertia ixx="0.052333333333333336" ixy="0.0" ixz="0.0" iyy="0.06193333333333334" iyz="0.0" izz="0.04373333333333334"/>
    </inertial>
  </link>
  <joint name="base_to_torso_lower" type="fixed">
    <origin rpy="0 0 0" xyz="0 0 0.13"/>
    <parent link="base_link"/>
    <child link="torso_lower_link"/>
  </joint>
  <link name="torso_upper_link">
    <visual>
      <origin rpy="0 0 0" xyz="0 0 0"/>
      <geometry>
        <box size="0.2 0.16 0.23"/>
      </geometry>
      <material name="torso_upper_link_mat">
        <color rgba="0.4 0.4 0.45 1"/>
      </material>
    </visual>
    <collision>
      <origin rpy="0 0 0" xyz="0 0 0"/>
      <geometry>
        <box size="0.2 0.16 0.23"/>
      </geometry>
    </collision>
    <inertial>
      <origin rpy="0 0 0" xyz="0 0 0"/>
      <mass value="8.0"/>
      <inertia ixx="0.052333333333333336" ixy="0.0" ixz="0.0" iyy="0.06193333333333334" iyz="0.0" izz="0.04373333333333334"/>
    </inertial>
  </link>
  <joint name="waist_rotation_joint" type="revolute">
    <origin rpy="0 0 0" xyz="0 0 0.23"/>
    <parent link="torso_lower_link"/>
    <child link="torso_upper_link"/>
    <axis xyz="0 0 1"/>
    <limit effort="60.0" lower="-1.57" upper="1.57" velocity="50.0"/>
    <dynamics damping="0.3" friction="0.08"/>
    <safety_controller k_position="15.0" k_velocity="10.0" soft_lower_limit="-1.45" soft_upper_limit="1.45"/>
  </joint>
  <link name="l_shoulder_pitch_link">
    <visual>
      <origin rpy="0 0 0" xyz="0 0 0"/>
      <geometry>
        <mesh filename="package://description/meshes/shoulder_housing.glb" scale="1 1 1"/>
      </geometry>
      <material name="l_shoulder_pitch_link_mat">
        <color rgba="0.2 0.55 0.3 1"/>
      </material>
    </visual>
    <collision>
      <origin rpy="0 0 0" xyz="0 0 0"/>
      <geometry>
        <box size="0.08 0.08 0.14"/>
      </geometry>
    </collision>
    <inertial>
      <origin rpy="0 0 0" xyz="0 0 0"/>
      <mass value="0.6"/>
      <inertia ixx="0.0013000000000000002" ixy="0.0" ixz="0.0" iyy="0.0013000000000000002" iyz="0.0" izz="0.00064"/>
    </inertial>
  </link>
  <link name="l_shoulder_roll_link">
    <visual>
      <origin rpy="0 0 0" xyz="0 0 0"/>
      <geometry>
        <mesh filename="package://description/meshes/shoulder_housing_cap.glb" scale="1 1 1"/>
      </geometry>
      <material name="l_shoulder_roll_link_mat">
        <color rgba="0.2 0.55 0.3 1"/>
      </material>
    </visual>
    <collision>
      <origin rpy="0 0 0" xyz="0 0 0"/>
      <geometry>
        <box size="0.1 0.1 0.12"/>
      </geometry>
    </collision>
    <inertial>
      <origin rpy="0 0 0" xyz="0 0 0"/>
      <mass value="0.5"/>
      <inertia ixx="0.0010166666666666668" ixy="0.0" ixz="0.0" iyy="0.0010166666666666668" iyz="0.0" izz="0.0008333333333333335"/>
    </inertial>
  </link>
  <link name="l_upper_arm_link">
    <visual>
      <origin rpy="0 0 0" xyz="0 0 0"/>
      <geometry>
        <box size="0.09 0.09 0.22"/>
      </geometry>
      <material name="l_upper_arm_link_mat">
        <color rgba="0.2 0.55 0.3 1"/>
      </material>
    </visual>
    <collision>
      <origin rpy="0 0 0" xyz="0 0 0"/>
      <geometry>
        <box size="0.09 0.09 0.22"/>
      </geometry>
    </collision>
    <inertial>
      <origin rpy="0 0 0" xyz="0 0 0"/>
      <mass value="0.7"/>
      <inertia ixx="0.003295833333333333" ixy="0.0" ixz="0.0" iyy="0.003295833333333333" iyz="0.0" izz="0.000945"/>
    </inertial>
  </link>
  <link name="l_forearm_link">
    <visual>
      <origin rpy="0 0 0" xyz="0 0 0"/>
      <geometry>
        <box size="0.08 0.08 0.2"/>
      </geometry>
      <material name="l_forearm_link_mat">
        <color rgba="0.15 0.45 0.25 1"/>
      </material>
    </visual>
    <collision>
      <origin rpy="0 0 0" xyz="0 0 0"/>
      <geometry>
        <box size="0.08 0.08 0.2"/>
      </geometry>
    </collision>
    <inertial>
      <origin rpy="0 0 0" xyz="0 0 0"/>
      <mass value="0.5"/>
      <inertia ixx="0.0019333333333333338" ixy="0.0" ixz="0.0" iyy="0.0019333333333333338" iyz="0.0" izz="0.0005333333333333334"/>
    </inertial>
  </link>
  <joint name="l_shoulder_pitch_joint" type="revolute">
    <origin rpy="0 0 0" xyz="0 0.12 0.10"/>
    <parent link="torso_upper_link"/>
    <child link="l_shoulder_pitch_link"/>
    <axis xyz="0 1 0"/>
    <limit effort="60.0" lower="-1.57" upper="3.14" velocity="50.0"/>
    <dynamics damping="0.3" friction="0.08"/>
    <safety_controller k_position="15.0" k_velocity="10.0" soft_lower_limit="-1.45" soft_upper_limit="3.02"/>
  </joint>
  <joint name="l_shoulder_roll_joint" type="revolute">
    <origin rpy="0 0 0" xyz="0 0 0.10"/>
    <parent link="l_shoulder_pitch_link"/>
    <child link="l_shoulder_roll_link"/>
    <axis xyz="1 0 0"/>
    <limit effort="60.0" lower="0.0" upper="3.14" velocity="50.0"/>
    <dynamics damping="0.3" friction="0.08"/>
    <safety_controller k_position="15.0" k_velocity="10.0" soft_lower_limit="0.12" soft_upper_limit="3.02"/>
  </joint>
  <joint name="l_upper_arm_yaw_joint" type="revolute">
    <origin rpy="0 0 0" xyz="0 0 0.08"/>
    <parent link="l_shoulder_roll_link"/>
    <child link="l_upper_arm_link"/>
    <axis xyz="0 0 1"/>
    <limit effort="60.0" lower="-1.57" upper="1.57" velocity="50.0"/>
    <dynamics damping="0.3" friction="0.08"/>
    <safety_controller k_position="15.0" k_velocity="10.0" soft_lower_limit="-1.45" soft_upper_limit="1.45"/>
  </joint>
  <joint name="l_elbow_pitch_joint" type="revolute">
    <origin rpy="0 0 0" xyz="0 0 -0.18"/>
    <parent link="l_upper_arm_link"/>
    <child link="l_forearm_link"/>
    <axis xyz="0 1 0"/>
    <limit effort="60.0" lower="0.0" upper="2.36" velocity="50.0"/>
    <dynamics damping="0.3" friction="0.08"/>
    <safety_controller k_position="15.0" k_velocity="10.0" soft_lower_limit="0.12" soft_upper_limit="2.24"/>
  </joint>
  <link name="r_shoulder_pitch_link">
    <visual>
      <origin rpy="0 0 3.14159" xyz="0 0 0"/>
      <geometry>
        <mesh filename="package://description/meshes/shoulder_housing.glb" scale="1 1 1"/>
      </geometry>
      <material name="r_shoulder_pitch_link_mat">
        <color rgba="0.25 0.35 0.65 1"/>
      </material>
    </visual>
    <collision>
      <origin rpy="0 0 0" xyz="0 0 0"/>
      <geometry>
        <box size="0.08 0.08 0.14"/>
      </geometry>
    </collision>
    <inertial>
      <origin rpy="0 0 0" xyz="0 0 0"/>
      <mass value="0.6"/>
      <inertia ixx="0.0013000000000000002" ixy="0.0" ixz="0.0" iyy="0.0013000000000000002" iyz="0.0" izz="0.00064"/>
    </inertial>
  </link>
  <link name="r_shoulder_roll_link">
    <visual>
      <origin rpy="0 0 3.14159" xyz="0 0 0"/>
      <geometry>
        <mesh filename="package://description/meshes/shoulder_housing_cap.glb" scale="1 1 1"/>
      </geometry>
      <material name="r_shoulder_roll_link_mat">
        <color rgba="0.25 0.35 0.65 1"/>
      </material>
    </visual>
    <collision>
      <origin rpy="0 0 0" xyz="0 0 0"/>
      <geometry>
        <box size="0.1 0.1 0.12"/>
      </geometry>
    </collision>
    <inertial>
      <origin rpy="0 0 0" xyz="0 0 0"/>
      <mass value="0.5"/>
      <inertia ixx="0.0010166666666666668" ixy="0.0" ixz="0.0" iyy="0.0010166666666666668" iyz="0.0" izz="0.0008333333333333335"/>
    </inertial>
  </link>
  <link name="r_upper_arm_link">
    <visual>
      <origin rpy="0 0 0" xyz="0 0 0"/>
      <geometry>
        <box size="0.09 0.09 0.22"/>
      </geometry>
      <material name="r_upper_arm_link_mat">
        <color rgba="0.25 0.35 0.65 1"/>
      </material>
    </visual>
    <collision>
      <origin rpy="0 0 0" xyz="0 0 0"/>
      <geometry>
        <box size="0.09 0.09 0.22"/>
      </geometry>
    </collision>
    <inertial>
      <origin rpy="0 0 0" xyz="0 0 0"/>
      <mass value="0.7"/>
      <inertia ixx="0.003295833333333333" ixy="0.0" ixz="0.0" iyy="0.003295833333333333" iyz="0.0" izz="0.000945"/>
    </inertial>
  </link>
  <link name="r_forearm_link">
    <visual>
      <origin rpy="0 0 0" xyz="0 0 0"/>
      <geometry>
        <box size="0.08 0.08 0.2"/>
      </geometry>
      <material name="r_forearm_link_mat">
        <color rgba="0.2 0.3 0.55 1"/>
      </material>
    </visual>
    <collision>
      <origin rpy="0 0 0" xyz="0 0 0"/>
      <geometry>
        <box size="0.08 0.08 0.2"/>
      </geometry>
    </collision>
    <inertial>
      <origin rpy="0 0 0" xyz="0 0 0"/>
      <mass value="0.5"/>
      <inertia ixx="0.0019333333333333338" ixy="0.0" ixz="0.0" iyy="0.0019333333333333338" iyz="0.0" izz="0.0005333333333333334"/>
    </inertial>
  </link>
  <joint name="r_shoulder_pitch_joint" type="revolute">
    <origin rpy="0 0 0" xyz="0 -0.12 0.10"/>
    <parent link="torso_upper_link"/>
    <child link="r_shoulder_pitch_link"/>
    <axis xyz="0 1 0"/>
    <limit effort="60.0" lower="-1.57" upper="3.14" velocity="50.0"/>
    <dynamics damping="0.3" friction="0.08"/>
    <safety_controller k_position="15.0" k_velocity="10.0" soft_lower_limit="-1.45" soft_upper_limit="3.02"/>
  </joint>
  <joint name="r_shoulder_roll_joint" type="revolute">
    <origin rpy="0 0 0" xyz="0 0 0.10"/>
    <parent link="r_shoulder_pitch_link"/>
    <child link="r_shoulder_roll_link"/>
    <axis xyz="1 0 0"/>
    <limit effort="60.0" lower="-3.14" upper="0.0" velocity="50.0"/>
    <dynamics damping="0.3" friction="0.08"/>
    <safety_controller k_position="15.0" k_velocity="10.0" soft_lower_limit="-3.02" soft_upper_limit="-0.12"/>
  </joint>
  <joint name="r_upper_arm_yaw_joint" type="revolute">
    <origin rpy="0 0 0" xyz="0 0 0.08"/>
    <parent link="r_shoulder_roll_link"/>
    <child link="r_upper_arm_link"/>
    <axis xyz="0 0 1"/>
    <limit effort="60.0" lower="-1.57" upper="1.57" velocity="50.0"/>
    <dynamics damping="0.3" friction="0.08"/>
    <safety_controller k_position="15.0" k_velocity="10.0" soft_lower_limit="-1.45" soft_upper_limit="1.45"/>
  </joint>
  <joint name="r_elbow_pitch_joint" type="revolute">
    <origin rpy="0 0 0" xyz="0 0 -0.18"/>
    <parent link="r_upper_arm_link"/>
    <child link="r_forearm_link"/>
    <axis xyz="0 1 0"/>
    <limit effort="60.0" lower="-2.36" upper="0.0" velocity="50.0"/>
    <dynamics damping="0.3" friction="0.08"/>
    <safety_controller k_position="15.0" k_velocity="10.0" soft_lower_limit="-2.24" soft_upper_limit="-0.12"/>
  </joint>
</robot>
